Workbook

Sheet Executive_Summary
A1: CMS synthetic claims - not real patient or provider performance.
A2: Executive summary
A3: Data: CMS DE-SynPUF sample 1, retrieved per data/data_manifest.json. Definitions: see Metric_Dictionary. Rates are formulas; the Pipeline columns hold the warehouse values they must equal.
A4: Year | B4: Beneficiaries | C4: Member_years | D4: Claims | E4: Paid_amount | F4: Admissions | G4: ED_proxy_visits | H4: Readmission_eligible | I4: Readmission_events | J4: Top5_paid_amount | K4: Pipeline_admissions_per_1000 | L4: Pipeline_readmission_proxy | M4: Pipeline_top5_share | N4: Paid_per_beneficiary | O4: Admissions_per_1000_member_years | P4: ED_proxy_per_1000_member_years | Q4: Readmission_proxy | R4: Top5_payment_share | S4: Check_vs_pipeline
A5: 2008 | B5: 116352 | C5: 107296.75 | D5: 2025978 | E5: 483275670 | F5: 26262 | G5: 22494 | H5: 25861 | I5: 3906 | J5: 234226340 | K5: 244.76044 | L5: 0.15103824 | M5: 0.48466404 | N5: =IF(B5>0,E5/B5,"") | O5: =IF(C5>0,F5/C5*1000,"") | P5: =IF(C5>0,G5/C5*1000,"") | Q5: =IF(H5>0,I5/H5,"") | R5: =IF(E5<>0,J5/E5,"") | S5: =IF(AND(ABS(O5-K5)<0.000001,ABS(R5-M5)<0.000001),"OK","CHECK")
A6: 2009 | B6: 114538 | C6: 106352.17 | D6: 2210561 | E6: 504801500 | F6: 24710 | G6: 26334 | H6: 24763 | I6: 1866 | J6: 197944970 | K6: 232.34129 | L6: 0.075354359 | M6: 0.39212437 | N6: =IF(B6>0,E6/B6,"") | O6: =IF(C6>0,F6/C6*1000,"") | P6: =IF(C6>0,G6/C6*1000,"") | Q6: =IF(H6>0,I6/H6,"") | R6: =IF(E6<>0,J6/E6,"") | S6: =IF(AND(ABS(O6-K6)<0.000001,ABS(R6-M6)<0.000001),"OK","CHECK")
A7: 2010 | B7: 112754 | C7: 104407.42 | D7: 1350500 | E7: 286712060 | F7: 13387 | G7: 13753 | H7: 13421 | I7: 577 | J7: 123536500 | K7: 128.21886 | L7: 0.042992325 | M7: 0.43087305 | N7: =IF(B7>0,E7/B7,"") | O7: =IF(C7>0,F7/C7*1000,"") | P7: =IF(C7>0,G7/C7*1000,"") | Q7: =IF(H7>0,I7/H7,"") | R7: =IF(E7<>0,J7/E7,"") | S7: =IF(AND(ABS(O7-K7)<0.000001,ABS(R7-M7)<0.000001),"OK","CHECK")
A10: Limitations
A11: What this workbook is: an operations review of CMS DE-SynPUF synthetic Medicare claims. It demonstrates a pipeline; it does not describe real Medicare.
A12: Not included: prescription drug events; any beneficiary-level rows; any claim of savings, fraud, or provider quality.
A13: Utilization risk tier is a transparent descriptive stratification, not CMS-HCC or any official risk adjustment.
A14: The 30-day readmission proxy is measure-inspired, not a certified measure. 2010 volumes are lower in the source, so year-to-year trends are not interpretable.

Sheet Monthly_Utilization
A1: CMS synthetic claims - not real patient or provider performance.
A2: Monthly utilization by care setting
A3: Claims per 1,000 members is a formula: claims / members x 1,000.
A4: Year_month | B4: Year | C4: Setting | D4: Members | E4: Claims | F4: Unique_beneficiaries | G4: Admissions | H4: ED_proxy_visits | I4: Outpatient_visits | J4: Carrier_service_lines | K4: Claims_per_1000_members
A5: 2008-01 | B5: 2008 | C5: carrier | D5: 111058 | E5: 65385 | F5: 28267 | J5: 127405 | K5: =IF(D5>0,E5/D5*1000,"")
A6: 2008-01 | B6: 2008 | C6: inpatient | D6: 111058 | E6: 1533 | F6: 1371 | G6: 1454 | K6: =IF(D6>0,E6/D6*1000,"")
A7: 2008-01 | B7: 2008 | C7: outpatient | D7: 111058 | E7: 10256 | F7: 8181 | H7: 796 | I7: 10256 | K7: =IF(D7>0,E7/D7*1000,"")
A8: 2008-02 | B8: 2008 | C8: carrier | D8: 110398 | E8: 102838 | F8: 41621 | J8: 200157 | K8: =IF(D8>0,E8/D8*1000,"")
A9: 2008-02 | B9: 2008 | C9: inpatient | D9: 110398 | E9: 1805 | F9: 1594 | G9: 1680 | K9: =IF(D9>0,E9/D9*1000,"")
A10: 2008-02 | B10: 2008 | C10: outpatient | D10: 110398 | E10: 15383 | F10: 11941 | H10: 1238 | I10: 15383 | K10: =IF(D10>0,E10/D10*1000,"")
A11: 2008-03 | B11: 2008 | C11: carrier | D11: 109809 | E11: 135921 | F11: 52408 | J11: 264760 | K11: =IF(D11>0,E11/D11*1000,"")
A12: 2008-03 | B12: 2008 | C12: inpatient | D12: 109809 | E12: 2300 | F12: 2076 | G12: 2161 | K12: =IF(D12>0,E12/D12*1000,"")
A13: 2008-03 | B13: 2008 | C13: outpatient | D13: 109809 | E13: 21051 | F13: 16046 | H13: 1707 | I13: 21051 | K13: =IF(D13>0,E13/D13*1000,"")
A14: 2008-04 | B14: 2008 | C14: carrier | D14: 109187 | E14: 146516 | F14: 56501 | J14: 285042 | K14: =IF(D14>0,E14/D14*1000,"")
A15: 2008-04 | B15: 2008 | C15: inpatient | D15: 109187 | E15: 2320 | F15: 2082 | G15: 2196 | K15: =IF(D15>0,E15/D15*1000,"")
A16: 2008-04 | B16: 2008 | C16: outpatient | D16: 109187 | E16: 23164 | F16: 17534 | H16: 1852 | I16: 23164 | K16: =IF(D16>0,E16/D16*1000,"")
A17: 2008-05 | B17: 2008 | C17: carrier | D17: 108578 | E17: 154711 | F17: 58937 | J17: 302802 | K17: =IF(D17>0,E17/D17*1000,"")
A18: 2008-05 | B18: 2008 | C18: inpatient | D18: 108578 | E18: 2585 | F18: 2268 | G18: 2420 | K18: =IF(D18>0,E18/D18*1000,"")
A19: 2008-05 | B19: 2008 | C19: outpatient | D19: 108578 | E19: 24918 | F19: 18786 | H19: 1924 | I19: 24918 | K19: =IF(D19>0,E19/D19*1000,"")
A20: 2008-06 | B20: 2008 | C20: carrier | D20: 107859 | E20: 152202 | F20: 59323 | J20: 297309 | K20: =IF(D20>0,E20/D20*1000,"")
A21: 2008-06 | B21: 2008 | C21: inpatient | D21: 107859 | E21: 2455 | F21: 2194 | G21: 2303 | K21: =IF(D21>0,E21/D21*1000,"")
A22: 2008-06 | B22: 2008 | C22: outpatient | D22: 107859 | E22: 25063 | F22: 19105 | H22: 1961 | I22: 25063 | K22: =IF(D22>0,E22/D22*1000,"")
A23: 2008-07 | B23: 2008 | C23: carrier | D23: 107171 | E23: 159898 | F23: 61091 | J23: 314742 | K23: =IF(D23>0,E23/D23*1000,"")
A24: 2008-07 | B24: 2008 | C24: inpatient | D24: 107171 | E24: 2467 | F24: 2233 | G24: 2342 | K24: =IF(D24>0,E24/D24*1000,"")
A25: 2008-07 | B25: 2008 | C25: outpatient | D25: 107171 | E25: 26414 | F25: 19968 | H25: 2024 | I25: 26414 | K25: =IF(D25>0,E25/D25*1000,"")
A26: 2008-08 | B26: 2008 | C26: carrier | D26: 106412 | E26: 160504 | F26: 61934 | J26: 313086 | K26: =IF(D26>0,E26/D26*1000,"")
A27: 2008-08 | B27: 2008 | C27: inpatient | D27: 106412 | E27: 2586 | F27: 2330 | G27: 2469 | K27: =IF(D27>0,E27/D27*1000,"")
A28: 2008-08 | B28: 2008 | C28: outpatient | D28: 106412 | E28: 27203 | F28: 20675 | H28: 2151 | I28: 27203 | K28: =IF(D28>0,E28/D28*1000,"")
A29: 2008-09 | B29: 2008 | C29: carrier | D29: 105655 | E29: 157037 | F29: 62000 | J29: 307921 | K29: =IF(D29>0,E29/D29*1000,"")
A30: 2008-09 | B30: 2008 | C30: inpatient | D30: 105655 | E30: 2454 | F30: 2257 | G30: 2347 | K30: =IF(D30>0,E30/D30*1000,"")
A31: 2008-09 | B31: 2008 | C31: outpatient | D31: 105655 | E31: 26418 | F31: 20264 | H31: 2170 | I31: 26418 | K31: =IF(D31>0,E31/D31*1000,"")
A32: 2008-10 | B32: 2008 | C32: carrier | D32: 104778 | E32: 161664 | F32: 62798 | J32: 317590 | K32: =IF(D32>0,E32/D32*1000,"")
A33: 2008-10 | B33: 2008 | C33: inpatient | D33: 104778 | E33: 2506 | F33: 2290 | G33: 2397 | K33: =IF(D33>0,E33/D33*1000,"")
A34: 2008-10 | B34: 2008 | C34: outpatient | D34: 104778 | E34: 27482 | F34: 20935 | H34: 2151 | I34: 27482 | K34: =IF(D34>0,E34/D34*1000,"")
A35: 2008-11 | B35: 2008 | C35: carrier | D35: 103848 | E35: 156810 | F35: 62327 | J35: 306947 | K35: =IF(D35>0,E35/D35*1000,"")
A36: 2008-11 | B36: 2008 | C36: inpatient | D36: 103848 | E36: 2341 | F36: 2161 | G36: 2241 | K36: =IF(D36>0,E36/D36*1000,"")
A37: 2008-11 | B37: 2008 | C37: outpatient | D37: 103848 | E37: 27104 | F37: 20973 | H37: 2165 | I37: 27104 | K37: =IF(D37>0,E37/D37*1000,"")
A38: 2008-12 | B38: 2008 | C38: carrier | D38: 102808 | E38: 161916 | F38: 63155 | J38: 319601 | K38: =IF(D38>0,E38/D38*1000,"")
A39: 2008-12 | B39: 2008 | C39: inpatient | D39: 102808 | E39: 2328 | F39: 2168 | G39: 2252 | K39: =IF(D39>0,E39/D39*1000,"")
A40: 2008-12 | B40: 2008 | C40: outpatient | D40: 102808 | E40: 28440 | F40: 21752 | H40: 2355 | I40: 28440 | K40: =IF(D40>0,E40/D40*1000,"")
...

Sheet Monthly_Payments
A1: CMS synthetic claims - not real patient or provider performance.
A2: Monthly payments by care setting
A3: Payment fields keep their CMS names; negative amounts are payment adjustments and are included.
A4: Year_month | B4: Year | C4: Setting | D4: Payment_source_field | E4: Claims | F4: Payment_amount | G4: Negative_payment_claims | H4: Zero_payment_claims | I4: Payment_per_claim
A5: 2008-01 | B5: 2008 | C5: carrier | D5: LINE_NCH_PMT_AMT_1..13 (sum of lines) | E5: 65385 | F5: 5504620 | G5: 0 | H5: 7131 | I5: =IF(E5>0,F5/E5,"")
A6: 2008-01 | B6: 2008 | C6: inpatient | D6: CLM_PMT_AMT (sum of segments) | E6: 1533 | F6: 14466480 | G6: 1 | H6: 54 | I6: =IF(E6>0,F6/E6,"")
A7: 2008-01 | B7: 2008 | C7: outpatient | D7: CLM_PMT_AMT (sum of segments) | E7: 10256 | F7: 3064860 | G7: 37 | H7: 430 | I7: =IF(E7>0,F7/E7,"")
A8: 2008-02 | B8: 2008 | C8: carrier | D8: LINE_NCH_PMT_AMT_1..13 (sum of lines) | E8: 102838 | F8: 8595400 | G8: 0 | H8: 11131 | I8: =IF(E8>0,F8/E8,"")
A9: 2008-02 | B9: 2008 | C9: inpatient | D9: CLM_PMT_AMT (sum of segments) | E9: 1805 | F9: 16289110 | G9: 0 | H9: 81 | I9: =IF(E9>0,F9/E9,"")
A10: 2008-02 | B10: 2008 | C10: outpatient | D10: CLM_PMT_AMT (sum of segments) | E10: 15383 | F10: 4480900 | G10: 40 | H10: 629 | I10: =IF(E10>0,F10/E10,"")
A11: 2008-03 | B11: 2008 | C11: carrier | D11: LINE_NCH_PMT_AMT_1..13 (sum of lines) | E11: 135921 | F11: 11396260 | G11: 0 | H11: 14838 | I11: =IF(E11>0,F11/E11,"")
A12: 2008-03 | B12: 2008 | C12: inpatient | D12: CLM_PMT_AMT (sum of segments) | E12: 2300 | F12: 20901530 | G12: 2 | H12: 92 | I12: =IF(E12>0,F12/E12,"")
A13: 2008-03 | B13: 2008 | C13: outpatient | D13: CLM_PMT_AMT (sum of segments) | E13: 21051 | F13: 5619130 | G13: 76 | H13: 839 | I13: =IF(E13>0,F13/E13,"")
A14: 2008-04 | B14: 2008 | C14: carrier | D14: LINE_NCH_PMT_AMT_1..13 (sum of lines) | E14: 146516 | F14: 12258090 | G14: 0 | H14: 15929 | I14: =IF(E14>0,F14/E14,"")
A15: 2008-04 | B15: 2008 | C15: inpatient | D15: CLM_PMT_AMT (sum of segments) | E15: 2320 | F15: 21728870 | G15: 3 | H15: 82 | I15: =IF(E15>0,F15/E15,"")
A16: 2008-04 | B16: 2008 | C16: outpatient | D16: CLM_PMT_AMT (sum of segments) | E16: 23164 | F16: 6427460 | G16: 79 | H16: 949 | I16: =IF(E16>0,F16/E16,"")
... A112: 2010-12 | B112: 2010 | C112: outpatient | D112: CLM_PMT_AMT (sum of segments) | E112: 6812 | F112: 1780490 | G112: 23 | H112: 239 | I112: =IF(E112>0,F112/E112,"")

Sheet Provider_Review
A1: CMS synthetic claims - not real patient or provider performance.
A2: Provider review list (SYNTHETIC flags only)
A3: Review flags are prompts to compare peers. They are not fraud, quality or performance findings. Provider IDs are synthetic.
A4: Year | B4: Provider_type | C4: Provider_id | D4: Claims | E4: Beneficiaries | F4: Payment_amount | G4: Peer_count | H4: Review_flag | I4: Reason_codes | J4: Payment_per_claim
A5: 2008 | B5: facility_inpatient | C5: 23006G | D5: 315 | E5: 239 | F5: 2897100 | G5: 2408 | H5: REVIEW | I5: HIGH_CLAIM_VOLUME | J5: =IF(D5>0,F5/D5,"")
A6: 2008 | B6: facility_inpatient | C6: 3600NG | D6: 228 | E6: 147 | F6: 2373900 | G6: 2408 | H6: REVIEW | I6: HIGH_CLAIM_VOLUME | J6: =IF(D6>0,F6/D6,"")
A7: 2008 | B7: facility_inpatient | C7: 1000AH | D7: 237 | E7: 212 | F7: 2319700 | G7: 2408 | H7: REVIEW | I7: HIGH_CLAIM_VOLUME | J7: =IF(D7>0,F7/D7,"")
A8: 2008 | B8: facility_inpatient | C8: 2100WC | D8: 167 | E8: 145 | F8: 1761000 | G8: 2408 | H8: REVIEW | I8: HIGH_CLAIM_VOLUME | J8: =IF(D8>0,F8/D8,"")
A9: 2008 | B9: facility_inpatient | C9: 3100JN | D9: 136 | E9: 100 | F9: 1619900 | G9: 2408 | H9: REVIEW | I9: HIGH_CLAIM_VOLUME | J9: =IF(D9>0,F9/D9,"")
A10: 2008 | B10: facility_inpatient | C10: 3400XN | D10: 162 | E10: 120 | F10: 1578000 | G10: 2408 | H10: REVIEW | I10: HIGH_CLAIM_VOLUME | J10: =IF(D10>0,F10/D10,"")
A11: 2008 | B11: facility_inpatient | C11: 4500DP | D11: 154 | E11: 104 | F11: 1520400 | G11: 2408 | H11: REVIEW | I11: HIGH_CLAIM_VOLUME | J11: =IF(D11>0,F11/D11,"")
A12: 2008 | B12: facility_inpatient | C12: 1401RR | D12: 181 | E12: 150 | F12: 1506900 | G12: 2408 | H12: REVIEW | I12: HIGH_CLAIM_VOLUME | J12: =IF(D12>0,F12/D12,"")
A13: 2008 | B13: facility_inpatient | C13: 1002DC | D13: 134 | E13: 105 | F13: 1501100 | G13: 2408 | H13: REVIEW | I13: HIGH_CLAIM_VOLUME | J13: =IF(D13>0,F13/D13,"")
A14: 2008 | B14: facility_inpatient | C14: 2600ZT | D14: 165 | E14: 132 | F14: 1487450 | G14: 2408 | H14: REVIEW | I14: HIGH_CLAIM_VOLUME | J14: =IF(D14>0,F14/D14,"")
A15: 2008 | B15: facility_inpatient | C15: 0501MA | D15: 126 | E15: 112 | F15: 1396200 | G15: 2408 | H15: REVIEW | I15: HIGH_CLAIM_VOLUME | J15: =IF(D15>0,F15/D15,"")
A16: 2008 | B16: facility_inpatient | C16: 0400AC | D16: 130 | E16: 85 | F16: 1377000 | G16: 2408 | H16: REVIEW | I16: HIGH_CLAIM_VOLUME | J16: =IF(D16>0,F16/D16,"")
... A1198: 2010 | B1198: facility_inpatient | C1198: 4900CN | D1198: 43 | E1198: 41 | F1198: 453000 | G1198: 2063 | H1198: REVIEW | I1198: HIGH_CLAIM_VOLUME | J1198: =IF(D1198>0,F1198/D1198,"")
A1199: 2010 | B1199: facility_inpatient | C1199: 1400RU | D1199: 29 | E1199: 27 | F1199: 448000 | G1199: 2063 | J1199: =IF(D1199>0,F1199/D1199,"")
A1200: 2010 | B1200: facility_inpatient | C1200: 0507AB | D1200: 37 | E1200: 35 | F1200: 439600 | G1200: 2063 | H1200: REVIEW | I1200: HIGH_CLAIM_VOLUME | J1200: =IF(D1200>0,F1200/D1200,"")
A1201: 2010 | B1201: facility_inpatient | C1201: 4401DM | D1201: 48 | E1201: 45 | F1201: 439020 | G1201: 2063 | H1201: REVIEW | I1201: HIGH_CLAIM_VOLUME | J1201: =IF(D1201>0,F1201/D1201,"")
A1202: 2010 | B1202: facility_inpatient | C1202: 0600GH | D1202: 34 | E1202: 32 | F1202: 431000 | G1202: 2063 | H1202: REVIEW | I1202: HIGH_CLAIM_VOLUME | J1202: =IF(D1202>0,F1202/D1202,"")
A1203: 2010 | B1203: facility_inpatient | C1203: 3400SP | D1203: 45 | E1203: 42 | F1203: 425800 | G1203: 2063 | H1203: REVIEW | I1203: HIGH_CLAIM_VOLUME | J1203: =IF(D1203>0,F1203/D1203,"")
A1204: 2010 | B1204: facility_inpatient | C1204: 2100NQ | D1204: 43 | E1204: 40 | F1204: 425300 | G1204: 2063 | H1204: REVIEW | I1204: HIGH_CLAIM_VOLUME | J1204: =IF(D1204>0,F1204/D1204,"")
A1205: 2010 | B1205: facility_inpatient | C1205: 1501ZA | D1205: 33 | E1205: 32 | F1205: 417600 | G1205: 2063 | H1205: REVIEW | I1205: HIGH_CLAIM_VOLUME | J1205: =IF(D1205>0,F1205/D1205,"")
A1206: 2010 | B1206: facility_inpatient | C1206: 3902XB | D1206: 47 | E1206: 42 | F1206: 415000 | G1206: 2063 | H1206: REVIEW | I1206: HIGH_CLAIM_VOLUME | J1206: =IF(D1206>0,F1206/D1206,"")
A1207: 2010 | B1207: facility_inpatient | C1207: 0700JR | D1207: 45 | E1207: 42 | F1207: 400500 | G1207: 2063 | H1207: REVIEW | I1207: HIGH_CLAIM_VOLUME | J1207: =IF(D1207>0,F1207/D1207,"")
A1208: 2010 | B1208: facility_inpatient | C1208: 0505KQ | D1208: 42 | E1208: 41 | F1208: 398900 | G1208: 2063 | H1208: REVIEW | I1208: HIGH_CLAIM_VOLUME | J1208: =IF(D1208>0,F1208/D1208,"")
A1209: 2010 | B1209: facility_inpatient | C1209: 5130XG | D1209: 33 | E1209: 27 | F1209: 378000 | G1209: 2063 | H1209: REVIEW | I1209: HIGH_CLAIM_VOLUME | J1209: =IF(D1209>0,F1209/D1209,"")
A1210: 2010 | B1210: facility_inpatient | C1210: 4500NJ | D1210: 43 | E1210: 43 | F1210: 373500 | G1210: 2063 | H1210: REVIEW | I1210: HIGH_CLAIM_VOLUME | J1210: =IF(D1210>0,F1210/D1210,"")
A1211: 2010 | B1211: facility_inpatient | C1211: 1800WP | D1211: 29 | E1211: 27 | F1211: 370000 | G1211: 2063 | J1211: =IF(D1211>0,F1211/D1211,"")
A1212: 2010 | B1212: facility_inpatient | C1212: 1001NA | D1212: 39 | E1212: 36 | F1212: 365000 | G1212: 2063 | H1212: REVIEW | I1212: HIGH_CLAIM_VOLUME | J1212: =IF(D1212>0,F1212/D1212,"")
A1213: 2010 | B1213: facility_inpatient | C1213: 14018H | D1213: 37 | E1213: 36 | F1213: 362000 | G1213: 2063 | H1213: REVIEW | I1213: HIGH_CLAIM_VOLUME | J1213: =IF(D1213>0,F1213/D1213,"")
A1214: 2010 | B1214: facility_inpatient | C1214: 3302BQ | D1214: 41 | E1214: 41 | F1214: 359700 | G1214: 2063 | H1214: REVIEW | I1214: HIGH_CLAIM_VOLUME | J1214: =IF(D1214>0,F1214/D1214,"")
A1215: 2010 | B1215: facility_inpatient | C1215: 1002ZT | D1215: 42 | E1215: 42 | F1215: 359000 | G1215: 2063 | H1215: REVIEW | I1215: HIGH_CLAIM_VOLUME | J1215: =IF(D1215>0,F1215/D1215,"")
A1216: 2010 | B1216: facility_inpatient | C1216: 4900NA | D1216: 32 | E1216: 31 | F1216: 355500 | G1216: 2063 | H1216: REVIEW | I1216: HIGH_CLAIM_VOLUME | J1216: =IF(D1216>0,F1216/D1216,"")
A1217: 2010 | B1217: facility_inpatient | C1217: 3600TU | D1217: 37 | E1217: 32 | F1217: 353700 | G1217: 2063 | H1217: REVIEW | I1217: HIGH_CLAIM_VOLUME | J1217: =IF(D1217>0,F1217/D1217,"")
A1218: 2010 | B1218: facility_inpatient | C1218: 0300CC | D1218: 41 | E1218: 38 | F1218: 349400 | G1218: 2063 | H1218: REVIEW | I1218: HIGH_CLAIM_VOLUME | J1218: =IF(D1218>0,F1218/D1218,"")
A1219: 2010 | B1219: facility_inpatient | C1219: 05018N | D1219: 45 | E1219: 42 | F1219: 348000 | G1219: 2063 | H1219: REVIEW | I1219: HIGH_CLAIM_VOLUME | J1219: =IF(D1219>0,F1219/D1219,"")
A1220: 2010 | B1220: facility_inpatient | C1220: 1000AQ | D1220: 36 | E1220: 36 | F1220: 346000 | G1220: 2063 | H1220: REVIEW | I1220: HIGH_CLAIM_VOLUME | J1220: =IF(D1220>0,F1220/D1220,"")
A1221: 2010 | B1221: facility_inpatient | C1221: 36008A | D1221: 35 | E1221: 34 | F1221: 343000 | G1221: 2063 | H1221: REVIEW | I1221: HIGH_CLAIM_VOLUME | J1221: =IF(D1221>0,F1221/D1221,"")
...

Sheet Readmission_Review
A1: CMS synthetic claims - not real patient or provider performance.
A2: 30-day readmission proxy by year and utilization risk tier
A3: Measure-inspired proxy, not a certified measure. Rate is a formula: readmitted / eligible index stays.
A4: Year | B4: Utilization_risk_tier | C4: Eligible_index_stays | D4: Readmitted_stays | E4: Excluded_died_in_stay | F4: Excluded_insufficient_followup | G4: Stays_considered | H4: Readmission_rate
A5: 2008 | B5: not_assessed | C5: 25861 | D5: 3906 | E5: 1 | F5: 0 | G5: 25862 | H5: =IF(C5>0,D5/C5,"")
A6: 2009 | B6: high | C6: 10737 | D6: 1108 | E6: 2 | F6: 0 | G6: 10739 | H6: =IF(C6>0,D6/C6,"")
A7: 2009 | B7: low | C7: 4958 | D7: 202 | E7: 0 | F7: 0 | G7: 4958 | H7: =IF(C7>0,D7/C7,"")
A8: 2009 | B8: medium | C8: 9068 | D8: 556 | E8: 0 | F8: 0 | G8: 9068 | H8: =IF(C8>0,D8/C8,"")
A9: 2010 | B9: high | C9: 4942 | D9: 304 | E9: 0 | F9: 194 | G9: 5136 | H9: =IF(C9>0,D9/C9,"")
A10: 2010 | B10: low | C10: 2695 | D10: 58 | E10: 1 | F10: 31 | G10: 2727 | H10: =IF(C10>0,D10/C10,"")
A11: 2010 | B11: medium | C11: 5784 | D11: 215 | E11: 0 | F11: 85 | G11: 5869 | H11: =IF(C11>0,D11/C11,"")

Sheet Member_Risk_Tiers
A1: CMS synthetic claims - not real patient or provider performance.
A2: Utilization risk tiers (descriptive stratification)
A3: Not CMS-HCC, RAF or official risk adjustment. Tier uses prior-year information only. Aggregates only, no beneficiary rows.
A4: Year | B4: Utilization_risk_tier | C4: Beneficiaries | D4: Member_years | E4: Payment_amount | F4: Admissions | G4: Payment_per_beneficiary | H4: Admissions_per_1000_member_years
A5: 2008 | B5: not_assessed | C5: 116352 | D5: 107296.75 | E5: 483275670 | F5: 26262 | G5: =IF(C5>0,E5/C5,"") | H5: =IF(D5>0,F5/D5*1000,"")
A6: 2009 | B6: high | C6: 20033 | D6: 19805.417 | E6: 215495080 | F6: 10455 | G6: =IF(C6>0,E6/C6,"") | H6: =IF(D6>0,F6/D6*1000,"")
A7: 2009 | B7: low | C7: 63349 | D7: 55725.167 | E7: 101967960 | F7: 5046 | G7: =IF(C7>0,E7/C7,"") | H7: =IF(D7>0,F7/D7*1000,"")
A8: 2009 | B8: medium | C8: 31156 | D8: 30821.583 | E8: 187338460 | F8: 9209 | G8: =IF(C8>0,E8/C8,"") | H8: =IF(D8>0,F8/D8*1000,"")
A9: 2010 | B9: high | C9: 25386 | D9: 25003.25 | E9: 115141480 | F9: 4796 | G9: =IF(C9>0,E9/C9,"") | H9: =IF(D9>0,F9/D9*1000,"")
A10: 2010 | B10: low | C10: 52546 | D10: 45073.583 | E10: 51548060 | F10: 2727 | G10: =IF(C10>0,E10/C10,"") | H10: =IF(D10>0,F10/D10*1000,"")
A11: 2010 | B11: medium | C11: 34822 | D11: 34330.583 | E11: 120022520 | F11: 5864 | G11: =IF(C11>0,E11/C11,"") | H11: =IF(D11>0,F11/D11*1000,"")

Sheet Data_Quality
A1: CMS synthetic claims - not real patient or provider performance.
A2: Data quality
A3: Counts from the pipeline. Duplicates, impossible dates and out-of-window claims are excluded from metrics and reported here.
A4: Check | B4: Setting | C4: Value
A5: Exact duplicate rows dropped | B5: inpatient | C5: 0
A6: Exact duplicate rows dropped | B6: outpatient | C6: 0
A7: Exact duplicate rows dropped | B7: carrier | C7: 0
A8: Impossible or missing dates | B8: inpatient | C8: 0
A9: Impossible or missing dates | B9: outpatient | C9: 278
A10: Impossible or missing dates | B10: carrier | C10: 0
A11: Outside study window | B11: inpatient | C11: 226
A12: Outside study window | B12: outpatient | C12: 312
A13: Outside study window | B13: carrier | C13: 0
A14: Negative payment claims | B14: inpatient | C14: 55
A15: Negative payment claims | B15: outpatient | C15: 2557
A16: Negative payment claims | B16: carrier | C16: 0
... A25: Orphan claims (beneficiary missing) | B25: all | C25: 0

Sheet Metric_Dictionary
A1: CMS synthetic claims - not real patient or provider performance.
A2: Metric dictionary
A3: Single source: config/metric_dictionary.yml.
A4: Metric | B4: Category | C4: Definition | D4: Numerator | E4: Denominator | F4: Exclusions | G4: Unit | H4: Source_fields | I4: Caveat
A5: Beneficiaries | B5: Population | C5: Synthetic beneficiaries with a row in the year's beneficiary summary file. | D5: Count of beneficiary-year rows | E5: n/a | F5: none | G5: beneficiaries | H5: DESYNPUF_ID (beneficiary summary) | I5: Synthetic people. DE-SynPUF is a 5 percent synthetic sample of 2008 beneficiaries.
A6: Member months | B6: Population | C6: Months a beneficiary contributes to rates. A beneficiary-year contributes min(Part A coverage months, months alive in the year), placed from January. | D6: Sum over beneficiary-years of min(BENE_HI_CVRAGE_TOT_MONS, months alive) | E6: n/a | F6: Deceased beneficiaries stop after the month of BENE_DEATH_DT | G6: member months | H6: BENE_HI_CVRAGE_TOT_MONS, BENE_DEATH_DT | I6: CMS gives a count of covered months, not which months. Placing them from January is an assumption.
A7: Claims per 1,000 member-years | B7: Utilization | C7: Analytic claims divided by member years, times 1,000. | D7: Analytic claims (beneficiary + CLM_ID within a setting, segments merged) | E7: Member months divided by 12 | F7: Claims with invalid dates, claims dated outside 2008-01-01 to 2010-12-31, duplicate rows | G7: claims per 1,000 member-years | H7: DESYNPUF_ID, CLM_ID, CLM_FROM_DT, CLM_THRU_DT, SEGMENT | I7: Inpatient claims are dated by admission date.
A8: Inpatient admissions per 1,000 member-years | B8: Utilization | C8: Continuous inpatient stays per 1,000 member-years. A claim admitted on or before the discharge date of the beneficiary's earlier stay continues that stay. | D8: Inpatient stays by admission date | E8: Member years | F8: Invalid or out-of-window inpatient claims | G8: admissions per 1,000 member-years | H8: CLM_ADMSN_DT, NCH_BENE_DSCHRG_DT, CLM_FROM_DT, CLM_THRU_DT | I8: Transfers are merged; no discharge status field exists to identify them directly.
A9: ED visit proxy per 1,000 member-years | B9: Utilization | C9: Outpatient claims carrying at least one HCPCS code from 99281 to 99285, per 1,000 member-years. | D9: Analytic outpatient claims with an ED evaluation and management code | E9: Member years | F9: none beyond analytic-claim rules | G9: ED proxy visits per 1,000 member-years | H9: HCPCS_CD_1 to HCPCS_CD_45 (outpatient) | I9: DE-SynPUF has no revenue center codes, so this is a code-based proxy, not a validated ED measure.
A10: Outpatient visits per 1,000 member-years | B10: Utilization | C10: Analytic outpatient claims per 1,000 member-years. | D10: Analytic outpatient claims | E10: Member years | F10: analytic-claim rules | G10: claims per 1,000 member-years | H10: outpatient claims file | I10: A claim is not necessarily a distinct visit.
A11: Carrier service lines | B11: Utilization | C11: Carrier line items (up to 13 per claim) that have a HCPCS code, a non-zero payment or a performing NPI. CMS pads unused slots with a 0.00 payment; those padded slots are not lines. | D11: Analytic carrier lines | E11: n/a | F11: analytic-claim rules | G11: lines | H11: HCPCS_CD_1..13, LINE_NCH_PMT_AMT_1..13, PRF_PHYSN_NPI_1..13 | I11: Line-level payment is the only carrier payment field.
A12: Total claim payment amount | B12: Payment | C12: Medicare trust fund payment on analytic claims. Institutional claims use CLM_PMT_AMT (segments summed); carrier claims use LINE_NCH_PMT_AMT_1..13 (lines summed). Negative amounts are payment adjustments and are included. | D12: Sum of payment on analytic claims | E12: n/a | F12: Invalid-date and out-of-window claims are reported separately | G12: US dollars (synthetic) | H12: CLM_PMT_AMT, LINE_NCH_PMT_AMT_1..13 | I12: Not a cost, charge or allowed amount. Beneficiary summary MEDREIMB_* fields do not tie to claim payments and are not used.
A13: Payment per beneficiary | B13: Payment | C13: Total claim payment amount divided by beneficiaries in the year. | D13: Total claim payment amount | E13: Beneficiary summary rows in the year | F13: analytic-claim rules | G13: US dollars per beneficiary (synthetic) | H13: CLM_PMT_AMT, LINE_NCH_PMT_AMT_1..13 | I13: Includes beneficiaries with no claims.
A14: Payment per admission | B14: Payment | C14: Inpatient payment divided by inpatient stays. | D14: Inpatient CLM_PMT_AMT on analytic claims | E14: Inpatient stays by admission year | F14: analytic-claim rules | G14: US dollars per admission (synthetic) | H14: CLM_PMT_AMT | I14: Payment on a claim dated by admission is attributed to the admission year.
A15: Payment concentration (top 5 percent) | B15: Payment | C15: Share of a year's payment held by the highest-paid ceil(5 percent of beneficiaries) beneficiaries. | D15: Payment of the top ceil(5 percent x N) beneficiaries | E15: Total payment in the year | F15: none | G15: share | H15: CLM_PMT_AMT, LINE_NCH_PMT_AMT_1..13 | I15: Ties are broken by beneficiary ID.
... A19: Provider review flag | B19: Provider operations | C19: A provider-year whose payment per claim or claim volume exceeds Q3 plus a multiple (default 3, Tukey far-out fence) of the interquartile range of its peers (same provider type, setting for facilities, and year), with a minimum claim count and peer count. The fence applies only when peers vary (IQR above zero). | D19: n/a | E19: n/a | F19: Groups with too few peers or claims, or with no spread among peers, are not flagged | G19: flag with reason codes | H19: PRVDR_NUM, PRF_PHYSN_NPI_1..13 | I19: A prompt for review only. It is not evidence of fraud, poor quality or provider performance.

Sheet Reconciliation
A1: CMS synthetic claims - not real patient or provider performance.
A2: Reconciliation: workbook totals versus DuckDB
A3: Workbook column: a formula over this workbook's own tables. DuckDB column: value read from the marts. Tolerance: half a cent for money, zero for counts.
A4: Check | B4: DuckDB | C4: Tolerance | D4: Workbook_value | E4: Variance | F4: Status
A5: Monthly claims (all settings) | B5: 5587039 | C5: 0 | D5: =SUM(Monthly_Utilization!E5:E112) | E5: =ABS(D5-B5) | F5: =IF(E5<=C5,"PASS","FAIL")
A6: Monthly admissions | B6: 64359 | C6: 0 | D6: =SUM(Monthly_Utilization!G5:G112) | E6: =ABS(D6-B6) | F6: =IF(E6<=C6,"PASS","FAIL")
A7: Monthly ED proxy visits | B7: 62581 | C7: 0 | D7: =SUM(Monthly_Utilization!H5:H112) | E7: =ABS(D7-B7) | F7: =IF(E7<=C7,"PASS","FAIL")
A8: Monthly paid amount | B8: 1274789230 | C8: 0.005 | D8: =SUM(Monthly_Payments!F5:F112) | E8: =ABS(D8-B8) | F8: =IF(E8<=C8,"PASS","FAIL")
A9: Monthly payment claims | B9: 5587039 | C9: 0 | D9: =SUM(Monthly_Payments!E5:E112) | E9: =ABS(D9-B9) | F9: =IF(E9<=C9,"PASS","FAIL")
A10: Executive: claims | B10: 5587039 | C10: 0 | D10: =SUM(Executive_Summary!D5:D7) | E10: =ABS(D10-B10) | F10: =IF(E10<=C10,"PASS","FAIL")
A11: Executive: paid amount | B11: 1274789230 | C11: 0.005 | D11: =SUM(Executive_Summary!E5:E7) | E11: =ABS(D11-B11) | F11: =IF(E11<=C11,"PASS","FAIL")
A12: Executive: admissions | B12: 64359 | C12: 0 | D12: =SUM(Executive_Summary!F5:F7) | E12: =ABS(D12-B12) | F12: =IF(E12<=C12,"PASS","FAIL")
A13: Executive: member years x 12 | B13: 3816676 | C13: 1e-06 | D13: =SUM(Executive_Summary!C5:C7)*12 | E13: =ABS(D13-B13) | F13: =IF(E13<=C13,"PASS","FAIL")
A14: Readmission stays considered | B14: 64359 | C14: 0 | D14: =SUM(Readmission_Review!G5:G11) | E14: =ABS(D14-B14) | F14: =IF(E14<=C14,"PASS","FAIL")
A16: Overall | B16: =IF(COUNTIF(F5:F14,"FAIL")=0,"ALL CHECKS PASS","REVIEW")
